Workbook

Sheet All_India_Index_Upto_April23 (1
A1: Sector | B1: Year | C1: Month | D1: Cereals and products | E1: Meat and fish | F1: Egg | G1: Milk and products | H1: Oils and fats | I1: Fruits | J1: Vegetables | K1: Pulses and products | L1: Sugar and Confectionery | M1: Spices | N1: Non-alcoholic beverages | O1: Prepared meals, snacks, sweets etc. | P1: Food and beverages | Q1: Pan, tobacco and intoxicants | R1: Clothing | S1: Footwear | T1: Clothing and footwear | U1: Housing | V1: Fuel and light | W1: Household goods and services | X1: Health | Y1: Transport and communication | Z1: Recreation and amusement | AA1: Education | AB1: Personal care and effects | AC1: Miscellaneous | AD1: General index
A2: Rural | B2: 2013 | C2: January | D2: 107.5 | E2: 106.3 | F2: 108.1 | G2: 104.9 | H2: 106.1 | I2: 103.9 | J2: 101.9 | K2: 106.1 | L2: 106.8 | M2: 103.1 | N2: 104.8 | O2: 106.7 | P2: 105.5 | Q2: 105.1 | R2: 106.5 | S2: 105.8 | T2: 106.4 | U2: NA | V2: 105.5 | W2: 104.8 | X2: 104 | Y2: 103.3 | Z2: 103.4 | AA2: 103.8 | AB2: 104.7 | AC2: 104 | AD2: 105.1
A3: Urban | B3: 2013 | C3: January | D3: 110.5 | E3: 109.1 | F3: 113 | G3: 103.6 | H3: 103.4 | I3: 102.3 | J3: 102.9 | K3: 105.8 | L3: 105.1 | M3: 101.8 | N3: 105.1 | O3: 107.9 | P3: 105.9 | Q3: 105.2 | R3: 105.9 | S3: 105 | T3: 105.8 | U3: 100.3 | V3: 105.4 | W3: 104.8 | X3: 104.1 | Y3: 103.2 | Z3: 102.9 | AA3: 103.5 | AB3: 104.3 | AC3: 103.7 | AD3: 104
A4: Rural+Urban | B4: 2013 | C4: January | D4: 108.4 | E4: 107.3 | F4: 110 | G4: 104.4 | H4: 105.1 | I4: 103.2 | J4: 102.2 | K4: 106 | L4: 106.2 | M4: 102.7 | N4: 104.9 | O4: 107.3 | P4: 105.6 | Q4: 105.1 | R4: 106.3 | S4: 105.5 | T4: 106.2 | U4: 100.3 | V4: 105.5 | W4: 104.8 | X4: 104 | Y4: 103.2 | Z4: 103.1 | AA4: 103.6 | AB4: 104.5 | AC4: 103.9 | AD4: 104.6
A5: Rural | B5: 2013 | C5: February | D5: 109.2 | E5: 108.7 | F5: 110.2 | G5: 105.4 | H5: 106.7 | I5: 104 | J5: 102.4 | K5: 105.9 | L5: 105.7 | M5: 103.1 | N5: 105.1 | O5: 107.7 | P5: 106.3 | Q5: 105.6 | R5: 107.1 | S5: 106.3 | T5: 107 | U5: NA | V5: 106.2 | W5: 105.2 | X5: 104.4 | Y5: 103.9 | Z5: 104 | AA5: 104.1 | AB5: 104.6 | AC5: 104.4 | AD5: 105.8
A6: Urban | B6: 2013 | C6: February | D6: 112.9 | E6: 112.9 | F6: 116.9 | G6: 104 | H6: 103.5 | I6: 103.1 | J6: 104.9 | K6: 104.1 | L6: 103.8 | M6: 102.3 | N6: 106 | O6: 109 | P6: 107.2 | Q6: 106 | R6: 106.6 | S6: 105.5 | T6: 106.4 | U6: 100.4 | V6: 105.7 | W6: 105.2 | X6: 104.7 | Y6: 104.4 | Z6: 103.3 | AA6: 103.7 | AB6: 104.3 | AC6: 104.3 | AD6: 104.7
A7: Rural+Urban | B7: 2013 | C7: February | D7: 110.4 | E7: 110.2 | F7: 112.8 | G7: 104.9 | H7: 105.5 | I7: 103.6 | J7: 103.2 | K7: 105.3 | L7: 105.1 | M7: 102.8 | N7: 105.5 | O7: 108.3 | P7: 106.6 | Q7: 105.7 | R7: 106.9 | S7: 106 | T7: 106.8 | U7: 100.4 | V7: 106 | W7: 105.2 | X7: 104.5 | Y7: 104.2 | Z7: 103.6 | AA7: 103.9 | AB7: 104.5 | AC7: 104.4 | AD7: 105.3
A8: Rural | B8: 2013 | C8: March | D8: 110.2 | E8: 108.8 | F8: 109.9 | G8: 105.6 | H8: 106.2 | I8: 105.7 | J8: 101.4 | K8: 105.7 | L8: 105 | M8: 103.3 | N8: 105.6 | O8: 108.2 | P8: 106.6 | Q8: 106.5 | R8: 107.6 | S8: 106.8 | T8: 107.5 | U8: NA | V8: 106.1 | W8: 105.6 | X8: 104.7 | Y8: 104.6 | Z8: 104 | AA8: 104.3 | AB8: 104.3 | AC8: 104.6 | AD8: 106
A9: Urban | B9: 2013 | C9: March | D9: 113.9 | E9: 111.4 | F9: 113.2 | G9: 104.3 | H9: 102.7 | I9: 104.9 | J9: 103.8 | K9: 103.5 | L9: 102.6 | M9: 102.4 | N9: 107 | O9: 109.8 | P9: 107.3 | Q9: 106.8 | R9: 107.2 | S9: 106 | T9: 107 | U9: 100.4 | V9: 106 | W9: 105.7 | X9: 105.2 | Y9: 105.5 | Z9: 103.5 | AA9: 103.8 | AB9: 104.2 | AC9: 104.9 | AD9: 105
A10: Rural+Urban | B10: 2013 | C10: March | D10: 111.4 | E10: 109.7 | F10: 111.2 | G10: 105.1 | H10: 104.9 | I10: 105.3 | J10: 102.2 | K10: 105 | L10: 104.2 | M10: 103 | N10: 106.2 | O10: 108.9 | P10: 106.9 | Q10: 106.6 | R10: 107.4 | S10: 106.5 | T10: 107.3 | U10: 100.4 | V10: 106.1 | W10: 105.6 | X10: 104.9 | Y10: 105.1 | Z10: 103.7 | AA10: 104 | AB10: 104.3 | AC10: 104.7 | AD10: 105.5
A11: Rural | B11: 2013 | C11: April | D11: 110.2 | E11: 109.5 | F11: 106.9 | G11: 106.3 | H11: 105.7 | I11: 108.3 | J11: 103.4 | K11: 105.7 | L11: 104.2 | M11: 103.2 | N11: 106.5 | O11: 108.8 | P11: 107.1 | Q11: 107.1 | R11: 108.1 | S11: 107.4 | T11: 108 | U11: NA | V11: 106.5 | W11: 106.1 | X11: 105.1 | Y11: 104.4 | Z11: 104.5 | AA11: 104.8 | AB11: 102.7 | AC11: 104.6 | AD11: 106.4
A12: Urban | B12: 2013 | C12: April | D12: 114.6 | E12: 113.4 | F12: 106 | G12: 104.7 | H12: 102.1 | I12: 109.5 | J12: 109.7 | K12: 104.6 | L12: 102 | M12: 103.5 | N12: 108.2 | O12: 110.6 | P12: 108.8 | Q12: 108.5 | R12: 107.9 | S12: 106.4 | T12: 107.7 | U12: 100.5 | V12: 106.4 | W12: 106.5 | X12: 105.7 | Y12: 105 | Z12: 104 | AA12: 105.2 | AB12: 103.2 | AC12: 105.1 | AD12: 105.7
A13: Rural+Urban | B13: 2013 | C13: April | D13: 111.6 | E13: 110.9 | F13: 106.6 | G13: 105.7 | H13: 104.4 | I13: 108.9 | J13: 105.5 | K13: 105.3 | L13: 103.5 | M13: 103.3 | N13: 107.2 | O13: 109.6 | P13: 107.7 | Q13: 107.5 | R13: 108 | S13: 107 | T13: 107.9 | U13: 100.5 | V13: 106.5 | W13: 106.3 | X13: 105.3 | Y13: 104.7 | Z13: 104.2 | AA13: 105 | AB13: 102.9 | AC13: 104.8 | AD13: 106.1
A14: Rural | B14: 2013 | C14: May | D14: 110.9 | E14: 109.8 | F14: 105.9 | G14: 107.5 | H14: 105.3 | I14: 108.1 | J14: 107.3 | K14: 106.1 | L14: 103.7 | M14: 104 | N14: 107.4 | O14: 109.9 | P14: 108.1 | Q14: 108.1 | R14: 108.8 | S14: 107.9 | T14: 108.6 | U14: NA | V14: 107.5 | W14: 106.8 | X14: 105.7 | Y14: 104.1 | Z14: 105 | AA14: 105.5 | AB14: 102.1 | AC14: 104.8 | AD14: 107.2
A15: Urban | B15: 2013 | C15: May | D15: 115.4 | E15: 114.2 | F15: 102.7 | G15: 105.5 | H15: 101.5 | I15: 110.6 | J15: 123.7 | K15: 105.2 | L15: 101.9 | M15: 105 | N15: 109.1 | O15: 111.3 | P15: 111.1 | Q15: 109.8 | R15: 108.5 | S15: 106.7 | T15: 108.3 | U15: 100.5 | V15: 107.2 | W15: 107.1 | X15: 106.2 | Y15: 103.9 | Z15: 104.6 | AA15: 105.7 | AB15: 102.6 | AC15: 104.9 | AD15: 106.6
A16: Rural+Urban | B16: 2013 | C16: May | D16: 112.3 | E16: 111.3 | F16: 104.7 | G16: 106.8 | H16: 103.9 | I16: 109.3 | J16: 112.9 | K16: 105.8 | L16: 103.1 | M16: 104.3 | N16: 108.1 | O16: 110.5 | P16: 109.2 | Q16: 108.6 | R16: 108.7 | S16: 107.4 | T16: 108.5 | U16: 100.5 | V16: 107.4 | W16: 106.9 | X16: 105.9 | Y16: 104 | Z16: 104.8 | AA16: 105.6 | AB16: 102.3 | AC16: 104.8 | AD16: 106.9
A17: Rural | B17: 2013 | C17: June | D17: 112.3 | E17: 112.1 | F17: 108.1 | G17: 108.3 | H17: 105.9 | I17: 109.2 | J17: 118 | K17: 106.8 | L17: 104.1 | M17: 105.4 | N17: 108.2 | O17: 111 | P17: 110.6 | Q17: 109 | R17: 109.7 | S17: 108.8 | T17: 109.5 | U17: NA | V17: 108.5 | W17: 107.5 | X17: 106.3 | Y17: 105 | Z17: 105.6 | AA17: 106.5 | AB17: 102.5 | AC17: 105.5 | AD17: 108.9
A18: Urban | B18: 2013 | C18: June | D18: 117 | E18: 120.1 | F18: 112.5 | G18: 107.3 | H18: 101.3 | I18: 112.4 | J18: 143.6 | K18: 105.4 | L18: 101.4 | M18: 106.4 | N18: 110 | O18: 112.2 | P18: 115 | Q18: 110.9 | R18: 109.2 | S18: 107.2 | T18: 108.9 | U18: 106.6 | V18: 108 | W18: 107.7 | X18: 106.5 | Y18: 105.2 | Z18: 105.2 | AA18: 108.1 | AB18: 103.3 | AC18: 106.1 | AD18: 109.7
A19: Rural+Urban | B19: 2013 | C19: June | D19: 113.8 | E19: 114.9 | F19: 109.8 | G19: 107.9 | H19: 104.2 | I19: 110.7 | J19: 126.7 | K19: 106.3 | L19: 103.2 | M19: 105.7 | N19: 109 | O19: 111.6 | P19: 112.2 | Q19: 109.5 | R19: 109.5 | S19: 108.1 | T19: 109.3 | U19: 106.6 | V19: 108.3 | W19: 107.6 | X19: 106.4 | Y19: 105.1 | Z19: 105.4 | AA19: 107.4 | AB19: 102.8 | AC19: 105.8 | AD19: 109.3
A20: Rural | B20: 2013 | C20: July | D20: 113.4 | E20: 114.9 | F20: 110.5 | G20: 109.3 | H20: 106.2 | I20: 110.3 | J20: 129.2 | K20: 107.1 | L20: 104.3 | M20: 106.4 | N20: 109.1 | O20: 112.1 | P20: 113.1 | Q20: 109.8 | R20: 110.5 | S20: 109.5 | T20: 110.3 | U20: NA | V20: 109.5 | W20: 108.3 | X20: 106.9 | Y20: 106.8 | Z20: 106.4 | AA20: 107.8 | AB20: 102.5 | AC20: 106.5 | AD20: 110.7
A21: Urban | B21: 2013 | C21: July | D21: 117.8 | E21: 119.2 | F21: 114 | G21: 108.3 | H21: 101.1 | I21: 113.2 | J21: 160.9 | K21: 105.1 | L21: 101.3 | M21: 107.5 | N21: 110.4 | O21: 113.1 | P21: 117.5 | Q21: 111.7 | R21: 109.8 | S21: 107.8 | T21: 109.5 | U21: 107.7 | V21: 108.6 | W21: 108.1 | X21: 107.1 | Y21: 107.3 | Z21: 105.9 | AA21: 110.1 | AB21: 103.2 | AC21: 107.3 | AD21: 111.4
A22: Rural+Urban | B22: 2013 | C22: July | D22: 114.8 | E22: 116.4 | F22: 111.9 | G22: 108.9 | H22: 104.3 | I22: 111.7 | J22: 140 | K22: 106.4 | L22: 103.3 | M22: 106.8 | N22: 109.6 | O22: 112.6 | P22: 114.7 | Q22: 110.3 | R22: 110.2 | S22: 108.8 | T22: 110 | U22: 107.7 | V22: 109.2 | W22: 108.2 | X22: 107 | Y22: 107.1 | Z22: 106.1 | AA22: 109.1 | AB22: 102.8 | AC22: 106.9 | AD22: 111
A23: Rural | B23: 2013 | C23: August | D23: 114.3 | E23: 115.4 | F23: 111.1 | G23: 110 | H23: 106.4 | I23: 110.8 | J23: 138.9 | K23: 107.4 | L23: 104.1 | M23: 106.9 | N23: 109.7 | O23: 112.6 | P23: 114.9 | Q23: 110.7 | R23: 111.3 | S23: 110.2 | T23: 111.1 | U23: NA | V23: 109.9 | W23: 108.7 | X23: 107.5 | Y23: 107.8 | Z23: 106.8 | AA23: 108.7 | AB23: 105 | AC23: 107.5 | AD23: 112.1
A24: Urban | B24: 2013 | C24: August | D24: 118.3 | E24: 120.4 | F24: 112.7 | G24: 108.9 | H24: 101.1 | I24: 108.7 | J24: 177 | K24: 104.7 | L24: 101 | M24: 108.5 | N24: 110.9 | O24: 114.3 | P24: 119.6 | Q24: 112.4 | R24: 110.6 | S24: 108.3 | T24: 110.2 | U24: 108.9 | V24: 109.3 | W24: 108.7 | X24: 107.6 | Y24: 108.1 | Z24: 106.5 | AA24: 110.8 | AB24: 106 | AC24: 108.3 | AD24: 112.7
A25: Rural+Urban | B25: 2013 | C25: August | D25: 115.6 | E25: 117.2 | F25: 111.7 | G25: 109.6 | H25: 104.5 | I25: 109.8 | J25: 151.8 | K25: 106.5 | L25: 103.1 | M25: 107.4 | N25: 110.2 | O25: 113.4 | P25: 116.6 | Q25: 111.2 | R25: 111 | S25: 109.4 | T25: 110.7 | U25: 108.9 | V25: 109.7 | W25: 108.7 | X25: 107.5 | Y25: 108 | Z25: 106.6 | AA25: 109.9 | AB25: 105.4 | AC25: 107.9 | AD25: 112.4
A26: Rural | B26: 2013 | C26: September | D26: 115.4 | E26: 115.7 | F26: 111.7 | G26: 111 | H26: 107.4 | I26: 110.9 | J26: 154 | K26: 108.1 | L26: 104.2 | M26: 107.9 | N26: 110.4 | O26: 114 | P26: 117.8 | Q26: 111.7 | R26: 112.7 | S26: 111.4 | T26: 112.5 | U26: NA | V26: 111.1 | W26: 109.6 | X26: 108.3 | Y26: 109.3 | Z26: 107.7 | AA26: 109.8 | AB26: 106.7 | AC26: 108.7 | AD26: 114.2
A27: Urban | B27: 2013 | C27: September | D27: 118.6 | E27: 119.1 | F27: 113.2 | G27: 109.6 | H27: 101.7 | I27: 103.2 | J27: 174.3 | K27: 105.1 | L27: 100.8 | M27: 109.1 | N27: 111.1 | O27: 115.4 | P27: 119.2 | Q27: 112.9 | R27: 111.4 | S27: 109 | T27: 111.1 | U27: 109.7 | V27: 109.5 | W27: 109.6 | X27: 107.9 | Y27: 110.4 | Z27: 107.4 | AA27: 111.2 | AB27: 106.9 | AC27: 109.4 | AD27: 113.2
A28: Rural+Urban | B28: 2013 | C28: September | D28: 116.4 | E28: 116.9 | F28: 112.3 | G28: 110.5 | H28: 105.3 | I28: 107.3 | J28: 160.9 | K28: 107.1 | L28: 103.1 | M28: 108.3 | N28: 110.7 | O28: 114.6 | P28: 118.3 | Q28: 112 | R28: 112.2 | S28: 110.4 | T28: 111.9 | U28: 109.7 | V28: 110.5 | W28: 109.6 | X28: 108.1 | Y28: 109.9 | Z28: 107.5 | AA28: 110.6 | AB28: 106.8 | AC28: 109 | AD28: 113.7
A29: Rural | B29: 2013 | C29: October | D29: 116.3 | E29: 115.4 | F29: 112.6 | G29: 111.7 | H29: 107.7 | I29: 113.2 | J29: 164.9 | K29: 108.3 | L29: 103.9 | M29: 108.2 | N29: 111.1 | O29: 114.9 | P29: 119.8 | Q29: 112.2 | R29: 113.6 | S29: 112.3 | T29: 113.4 | U29: NA | V29: 111.6 | W29: 110.4 | X29: 108.9 | Y29: 109.3 | Z29: 108.3 | AA29: 110.2 | AB29: 107.5 | AC29: 109.1 | AD29: 115.5
A30: Urban | B30: 2013 | C30: October | D30: 118.9 | E30: 118.1 | F30: 114.5 | G30: 110.4 | H30: 102.3 | I30: 106.2 | J30: 183.5 | K30: 105.3 | L30: 100.2 | M30: 109.6 | N30: 111.4 | O30: 116 | P30: 120.8 | Q30: 113.5 | R30: 112.5 | S30: 109.7 | T30: 112 | U30: 110.5 | V30: 109.7 | W30: 110.2 | X30: 108.2 | Y30: 109.7 | Z30: 108 | AA30: 111.3 | AB30: 107.3 | AC30: 109.4 | AD30: 114
A31: Rural+Urban | B31: 2013 | C31: October | D31: 117.1 | E31: 116.3 | F31: 113.3 | G31: 111.2 | H31: 105.7 | I31: 109.9 | J31: 171.2 | K31: 107.3 | L31: 102.7 | M31: 108.7 | N31: 111.2 | O31: 115.4 | P31: 120.2 | Q31: 112.5 | R31: 113.2 | S31: 111.2 | T31: 112.8 | U31: 110.5 | V31: 110.9 | W31: 110.3 | X31: 108.6 | Y31: 109.5 | Z31: 108.1 | AA31: 110.8 | AB31: 107.4 | AC31: 109.2 | AD31: 114.8
A32: Rural | B32: 2013 | C32: November | D32: 117.3 | E32: 114.9 | F32: 116.2 | G32: 112.8 | H32: 108.9 | I32: 116.6 | J32: 178.1 | K32: 109.1 | L32: 103.6 | M32: 109 | N32: 111.8 | O32: 116 | P32: 122.5 | Q32: 112.8 | R32: 114.6 | S32: 113.1 | T32: 114.4 | U32: NA | V32: 112.6 | W32: 111.3 | X32: 109.7 | Y32: 109.6 | Z32: 108.7 | AA32: 111 | AB32: 108.2 | AC32: 109.8 | AD32: 117.4
A33: Urban | B33: 2013 | C33: November | D33: 119.8 | E33: 116.3 | F33: 122.6 | G33: 112 | H33: 103.2 | I33: 110 | J33: 192.8 | K33: 106.3 | L33: 99.5 | M33: 110.3 | N33: 111.8 | O33: 117.1 | P33: 122.9 | Q33: 114.1 | R33: 113.5 | S33: 110.3 | T33: 113 | U33: 111.1 | V33: 110 | W33: 110.9 | X33: 108.6 | Y33: 109.5 | Z33: 108.5 | AA33: 111.3 | AB33: 107.9 | AC33: 109.6 | AD33: 115
A34: Rural+Urban | B34: 2013 | C34: November | D34: 118.1 | E34: 115.4 | F34: 118.7 | G34: 112.5 | H34: 106.8 | I34: 113.5 | J34: 183.1 | K34: 108.2 | L34: 102.2 | M34: 109.4 | N34: 111.8 | O34: 116.5 | P34: 122.6 | Q34: 113.1 | R34: 114.2 | S34: 111.9 | T34: 113.8 | U34: 111.1 | V34: 111.6 | W34: 111.1 | X34: 109.3 | Y34: 109.5 | Z34: 108.6 | AA34: 111.2 | AB34: 108.1 | AC34: 109.7 | AD34: 116.3
A35: Rural | B35: 2013 | C35: December | D35: 118.4 | E35: 115.9 | F35: 120.4 | G35: 113.8 | H35: 109.5 | I35: 115.5 | J35: 145.7 | K35: 109.5 | L35: 102.9 | M35: 109.8 | N35: 112.1 | O35: 116.8 | P35: 118.7 | Q35: 113.6 | R35: 115.8 | S35: 114 | T35: 115.5 | U35: NA | V35: 112.8 | W35: 112.1 | X35: 110.1 | Y35: 109.9 | Z35: 109.2 | AA35: 111.6 | AB35: 108.1 | AC35: 110.1 | AD35: 115.5
A36: Urban | B36: 2013 | C36: December | D36: 120.5 | E36: 118.1 | F36: 128.5 | G36: 112.8 | H36: 103.4 | I36: 110.7 | J36: 144.8 | K36: 107.1 | L36: 98.6 | M36: 111.9 | N36: 112.1 | O36: 118.1 | P36: 117.8 | Q36: 115 | R36: 114.2 | S36: 110.9 | T36: 113.7 | U36: 110.7 | V36: 110.4 | W36: 111.3 | X36: 109 | Y36: 109.7 | Z36: 108.9 | AA36: 111.4 | AB36: 107.7 | AC36: 109.8 | AD36: 113.3
A37: Rural+Urban | B37: 2013 | C37: December | D37: 119.1 | E37: 116.7 | F37: 123.5 | G37: 113.4 | H37: 107.3 | I37: 113.3 | J37: 145.4 | K37: 108.7 | L37: 101.5 | M37: 110.5 | N37: 112.1 | O37: 117.4 | P37: 118.4 | Q37: 114 | R37: 115.2 | S37: 112.7 | T37: 114.8 | U37: 110.7 | V37: 111.9 | W37: 111.7 | X37: 109.7 | Y37: 109.8 | Z37: 109 | AA37: 111.5 | AB37: 107.9 | AC37: 110 | AD37: 114.5
A38: Rural | B38: 2014 | C38: January | D38: 118.9 | E38: 117.1 | F38: 120.5 | G38: 114.4 | H38: 109 | I38: 115.5 | J38: 123.9 | K38: 109.6 | L38: 101.8 | M38: 110.2 | N38: 112.4 | O38: 117.3 | P38: 116 | Q38: 114 | R38: 116.5 | S38: 114.5 | T38: 116.2 | U38: NA | V38: 113 | W38: 112.6 | X38: 110.6 | Y38: 110.5 | Z38: 109.6 | AA38: 111.8 | AB38: 108.3 | AC38: 110.6 | AD38: 114.2
A39: Urban | B39: 2014 | C39: January | D39: 121.2 | E39: 122 | F39: 129.9 | G39: 113.6 | H39: 102.9 | I39: 112.1 | J39: 118.9 | K39: 107.5 | L39: 96.9 | M39: 112.7 | N39: 112.1 | O39: 119 | P39: 115.5 | Q39: 115.7 | R39: 114.8 | S39: 111.3 | T39: 114.3 | U39: 111.6 | V39: 111 | W39: 111.9 | X39: 109.7 | Y39: 110.8 | Z39: 109.8 | AA39: 111.5 | AB39: 108 | AC39: 110.5 | AD39: 112.9
A40: Rural+Urban | B40: 2014 | C40: January | D40: 119.6 | E40: 118.8 | F40: 124.1 | G40: 114.1 | H40: 106.8 | I40: 113.9 | J40: 122.2 | K40: 108.9 | L40: 100.2 | M40: 111 | N40: 112.3 | O40: 118.1 | P40: 115.8 | Q40: 114.5 | R40: 115.8 | S40: 113.2 | T40: 115.4 | U40: 111.6 | V40: 112.2 | W40: 112.3 | X40: 110.3 | Y40: 110.7 | Z40: 109.7 | AA40: 111.6 | AB40: 108.2 | AC40: 110.6 | AD40: 113.6
...

Sheet All_India_Index_Upto_April23
A1: Sector | B1: Year | C1: Month | D1: Cereals and products | E1: Meat and fish | F1: Egg | G1: Milk and products | H1: Oils and fats | I1: Fruits | J1: Vegetables | K1: Pulses and products | L1: Sugar and Confectionery | M1: Spices | N1: Non-alcoholic beverages | O1: Prepared meals, s149.08cks, sweets etc. | P1: Food and beverages | Q1: Pan, tobacco and intoxicants | R1: Clothing | S1: Footwear | T1: Clothing and footwear | U1: Housing | V1: Fuel and light | W1: Household goods and services | X1: Health | Y1: Transport and communication | Z1: Recreation and amusement | AA1: Education | AB1: Perso133.35l care and effects | AC1: Miscellaneous | AD1: General index | AE1: Mon_Year
A2: Rural | B2: 2013 | C2: January | D2: 107.5 | E2: 106.3 | F2: 108.1 | G2: 104.9 | H2: 106.1 | I2: 103.9 | J2: 101.9 | K2: 106.1 | L2: 106.8 | M2: 103.1 | N2: 104.8 | O2: 106.7 | P2: 105.5 | Q2: 105.1 | R2: 106.5 | S2: 105.8 | T2: 106.4 | U2: 139.26 | V2: 105.5 | W2: 104.8 | X2: 104 | Y2: 103.3 | Z2: 103.4 | AA2: 103.8 | AB2: 104.7 | AC2: 104 | AD2: 105.1 | AE2: 2013-01 | AF2: =TEXT(AE2, "YYYY-MM") -> 2013-01
A3: Urban | B3: 2013 | C3: January | D3: 110.5 | E3: 109.1 | F3: 113 | G3: 103.6 | H3: 103.4 | I3: 102.3 | J3: 102.9 | K3: 105.8 | L3: 105.1 | M3: 101.8 | N3: 105.1 | O3: 107.9 | P3: 105.9 | Q3: 105.2 | R3: 105.9 | S3: 105 | T3: 105.8 | U3: 100.3 | V3: 105.4 | W3: 104.8 | X3: 104.1 | Y3: 103.2 | Z3: 102.9 | AA3: 103.5 | AB3: 104.3 | AC3: 103.7 | AD3: 104 | AE3: 2013-01 | AF3: =TEXT(AE3, "YYYY-MM") -> 2013-01
A4: Rural+Urban | B4: 2013 | C4: January | D4: 108.4 | E4: 107.3 | F4: 110 | G4: 104.4 | H4: 105.1 | I4: 103.2 | J4: 102.2 | K4: 106 | L4: 106.2 | M4: 102.7 | N4: 104.9 | O4: 107.3 | P4: 105.6 | Q4: 105.1 | R4: 106.3 | S4: 105.5 | T4: 106.2 | U4: 100.3 | V4: 105.5 | W4: 104.8 | X4: 104 | Y4: 103.2 | Z4: 103.1 | AA4: 103.6 | AB4: 104.5 | AC4: 103.9 | AD4: 104.6 | AE4: 2013-01 | AF4: =TEXT(AE4, "YYYY-MM") -> 2013-01
A5: Rural | B5: 2013 | C5: February | D5: 109.2 | E5: 108.7 | F5: 110.2 | G5: 105.4 | H5: 106.7 | I5: 104 | J5: 102.4 | K5: 105.9 | L5: 105.7 | M5: 103.1 | N5: 105.1 | O5: 107.7 | P5: 106.3 | Q5: 105.6 | R5: 107.1 | S5: 106.3 | T5: 107 | U5: 139.26 | V5: 106.2 | W5: 105.2 | X5: 104.4 | Y5: 103.9 | Z5: 104 | AA5: 104.1 | AB5: 104.6 | AC5: 104.4 | AD5: 105.8 | AE5: 2013-02 | AF5: =TEXT(AE5, "YYYY-MM") -> 2013-02
A6: Urban | B6: 2013 | C6: February | D6: 112.9 | E6: 112.9 | F6: 116.9 | G6: 104 | H6: 103.5 | I6: 103.1 | J6: 104.9 | K6: 104.1 | L6: 103.8 | M6: 102.3 | N6: 106 | O6: 109 | P6: 107.2 | Q6: 106 | R6: 106.6 | S6: 105.5 | T6: 106.4 | U6: 100.4 | V6: 105.7 | W6: 105.2 | X6: 104.7 | Y6: 104.4 | Z6: 103.3 | AA6: 103.7 | AB6: 104.3 | AC6: 104.3 | AD6: 104.7 | AE6: 2013-02 | AF6: =TEXT(AE6, "YYYY-MM") -> 2013-02
A7: Rural+Urban | B7: 2013 | C7: February | D7: 110.4 | E7: 110.2 | F7: 112.8 | G7: 104.9 | H7: 105.5 | I7: 103.6 | J7: 103.2 | K7: 105.3 | L7: 105.1 | M7: 102.8 | N7: 105.5 | O7: 108.3 | P7: 106.6 | Q7: 105.7 | R7: 106.9 | S7: 106 | T7: 106.8 | U7: 100.4 | V7: 106 | W7: 105.2 | X7: 104.5 | Y7: 104.2 | Z7: 103.6 | AA7: 103.9 | AB7: 104.5 | AC7: 104.4 | AD7: 105.3 | AE7: 2013-02 | AF7: =TEXT(AE7, "YYYY-MM") -> 2013-02
A8: Rural | B8: 2013 | C8: March | D8: 110.2 | E8: 108.8 | F8: 109.9 | G8: 105.6 | H8: 106.2 | I8: 105.7 | J8: 101.4 | K8: 105.7 | L8: 105 | M8: 103.3 | N8: 105.6 | O8: 108.2 | P8: 106.6 | Q8: 106.5 | R8: 107.6 | S8: 106.8 | T8: 107.5 | U8: 139.26 | V8: 106.1 | W8: 105.6 | X8: 104.7 | Y8: 104.6 | Z8: 104 | AA8: 104.3 | AB8: 104.3 | AC8: 104.6 | AD8: 106 | AE8: 2013-03 | AF8: =TEXT(AE8, "YYYY-MM") -> 2013-03
A9: Urban | B9: 2013 | C9: March | D9: 113.9 | E9: 111.4 | F9: 113.2 | G9: 104.3 | H9: 102.7 | I9: 104.9 | J9: 103.8 | K9: 103.5 | L9: 102.6 | M9: 102.4 | N9: 107 | O9: 109.8 | P9: 107.3 | Q9: 106.8 | R9: 107.2 | S9: 106 | T9: 107 | U9: 100.4 | V9: 106 | W9: 105.7 | X9: 105.2 | Y9: 105.5 | Z9: 103.5 | AA9: 103.8 | AB9: 104.2 | AC9: 104.9 | AD9: 105 | AE9: 2013-03 | AF9: =TEXT(AE9, "YYYY-MM") -> 2013-03
A10: Rural+Urban | B10: 2013 | C10: March | D10: 111.4 | E10: 109.7 | F10: 111.2 | G10: 105.1 | H10: 104.9 | I10: 105.3 | J10: 102.2 | K10: 105 | L10: 104.2 | M10: 103 | N10: 106.2 | O10: 108.9 | P10: 106.9 | Q10: 106.6 | R10: 107.4 | S10: 106.5 | T10: 107.3 | U10: 100.4 | V10: 106.1 | W10: 105.6 | X10: 104.9 | Y10: 105.1 | Z10: 103.7 | AA10: 104 | AB10: 104.3 | AC10: 104.7 | AD10: 105.5 | AE10: 2013-03 | AF10: =TEXT(AE10, "YYYY-MM") -> 2013-03
A11: Rural | B11: 2013 | C11: April | D11: 110.2 | E11: 109.5 | F11: 106.9 | G11: 106.3 | H11: 105.7 | I11: 108.3 | J11: 103.4 | K11: 105.7 | L11: 104.2 | M11: 103.2 | N11: 106.5 | O11: 108.8 | P11: 107.1 | Q11: 107.1 | R11: 108.1 | S11: 107.4 | T11: 108 | U11: 139.26 | V11: 106.5 | W11: 106.1 | X11: 105.1 | Y11: 104.4 | Z11: 104.5 | AA11: 104.8 | AB11: 102.7 | AC11: 104.6 | AD11: 106.4 | AE11: 2013-04 | AF11: =TEXT(AE11, "YYYY-MM") -> 2013-04
A12: Urban | B12: 2013 | C12: April | D12: 114.6 | E12: 113.4 | F12: 106 | G12: 104.7 | H12: 102.1 | I12: 109.5 | J12: 109.7 | K12: 104.6 | L12: 102 | M12: 103.5 | N12: 108.2 | O12: 110.6 | P12: 108.8 | Q12: 108.5 | R12: 107.9 | S12: 106.4 | T12: 107.7 | U12: 100.5 | V12: 106.4 | W12: 106.5 | X12: 105.7 | Y12: 105 | Z12: 104 | AA12: 105.2 | AB12: 103.2 | AC12: 105.1 | AD12: 105.7 | AE12: 2013-04 | AF12: =TEXT(AE12, "YYYY-MM") -> 2013-04
A13: Rural+Urban | B13: 2013 | C13: April | D13: 111.6 | E13: 110.9 | F13: 106.6 | G13: 105.7 | H13: 104.4 | I13: 108.9 | J13: 105.5 | K13: 105.3 | L13: 103.5 | M13: 103.3 | N13: 107.2 | O13: 109.6 | P13: 107.7 | Q13: 107.5 | R13: 108 | S13: 107 | T13: 107.9 | U13: 100.5 | V13: 106.5 | W13: 106.3 | X13: 105.3 | Y13: 104.7 | Z13: 104.2 | AA13: 105 | AB13: 102.9 | AC13: 104.8 | AD13: 106.1 | AE13: 2013-04 | AF13: =TEXT(AE13, "YYYY-MM") -> 2013-04
... A292: Rural+Urban | B292: 2021 | C292: February | D292: 144.3 | E292: 186.5 | F292: 168.7 | G292: 154.7 | H292: 158.7 | I292: 150.7 | J292: 160 | K292: 158.8 | L292: 112.8 | M292: 164.2 | N292: 155.5 | O292: 167.5 | P292: 156.9 | Q292: 188.3 | R292: 157.2 | S292: 147.4 | T292: 155.8 | U292: 159.8 | V292: 152.4 | W292: 150.9 | X292: 161.3 | Y292: 145.1 | Z292: 151.5 | AA292: 159.5 | AB292: 155.8 | AC292: 153.4 | AD292: 156.6 | AE292: 2021-02 | AF292: =TEXT(AE292, "YYYY-MM") -> 2021-02
A293: Rural | B293: 2021 | C293: March | D293: 142.5 | E293: 189.4 | F293: 163.2 | G293: 154.5 | H293: 168.2 | I293: 150.5 | J293: 141 | K293: 159.2 | L293: 111.7 | M293: 164 | N293: 160.6 | O293: 166.4 | P293: 154.5 | Q293: 186.1 | R293: 159.6 | S293: 154.4 | T293: 158.9 | U293: - | V293: 156 | W293: 154.8 | X293: 164.6 | Y293: 151.3 | Z293: 157.8 | AA293: 163.8 | AB293: 153.1 | AC293: 157.3 | AD293: 156.7 | AE293: 2021-03 | AF293: =TEXT(AE293, "YYYY-MM") -> 2021-03
A294: Urban | B294: 2021 | C294: March | D294: 147.5 | E294: 197.5 | F294: 164.7 | G294: 155.6 | H294: 156.4 | I294: 157.3 | J294: 166.1 | K294: 161.1 | L294: 114.3 | M294: 162.6 | N294: 150.7 | O294: 170.3 | P294: 160.4 | Q294: 193.5 | R294: 155.1 | S294: 138.7 | T294: 152.6 | U294: 159.9 | V294: 154.8 | W294: 147.2 | X294: 156.9 | Y294: 141.7 | Z294: 148.6 | AA294: 157.6 | AB294: 154.9 | AC294: 150 | AD294: 156.9 | AE294: 2021-03 | AF294: =TEXT(AE294, "YYYY-MM") -> 2021-03
A295: Rural+Urban | B295: 2021 | C295: March | D295: 144.1 | E295: 192.2 | F295: 163.8 | G295: 154.9 | H295: 163.9 | I295: 153.7 | J295: 149.5 | K295: 159.8 | L295: 112.6 | M295: 163.5 | N295: 156.5 | O295: 168.2 | P295: 156.7 | Q295: 188.1 | R295: 157.8 | S295: 147.9 | T295: 156.4 | U295: 159.9 | V295: 155.5 | W295: 151.2 | X295: 161.7 | Y295: 146.2 | Z295: 152.6 | AA295: 160.2 | AB295: 153.8 | AC295: 153.8 | AD295: 156.8 | AE295: 2021-03 | AF295: =TEXT(AE295, "YYYY-MM") -> 2021-03
A296: Rural | B296: 2021 | C296: April | D296: 142.7 | E296: 195.5 | F296: 163.4 | G296: 155 | H296: 175.2 | I296: 160.6 | J296: 135.1 | K296: 161.1 | L296: 112.2 | M296: 164.4 | N296: 161.9 | O296: 166.8 | P296: 155.6 | Q296: 186.8 | R296: 160.7 | S296: 155.1 | T296: 159.9 | U296: - | V296: 156 | W296: 155.5 | X296: 165.3 | Y296: 151.7 | Z296: 158.6 | AA296: 164.1 | AB296: 154.6 | AC296: 158 | AD296: 157.6 | AE296: 2021-04 | AF296: =TEXT(AE296, "YYYY-MM") -> 2021-04
A297: Urban | B297: 2021 | C297: April | D297: 147.6 | E297: 202.5 | F297: 166.4 | G297: 156 | H297: 161.4 | I297: 168.8 | J297: 161.6 | K297: 162.8 | L297: 114.8 | M297: 162.8 | N297: 151.5 | O297: 171.4 | P297: 162 | Q297: 194.4 | R297: 155.9 | S297: 139.3 | T297: 153.4 | U297: 161.4 | V297: 154.9 | W297: 147.6 | X297: 157.5 | Y297: 142.1 | Z297: 149.1 | AA297: 157.6 | AB297: 156.6 | AC297: 150.5 | AD297: 158 | AE297: 2021-04 | AF297: =TEXT(AE297, "YYYY-MM") -> 2021-04
A298: Rural+Urban | B298: 2021 | C298: April | D298: 144.3 | E298: 198 | F298: 164.6 | G298: 155.4 | H298: 170.1 | I298: 164.4 | J298: 144.1 | K298: 161.7 | L298: 113.1 | M298: 163.9 | N298: 157.6 | O298: 168.9 | P298: 158 | Q298: 188.8 | R298: 158.8 | S298: 148.5 | T298: 157.3 | U298: 161.4 | V298: 155.6 | W298: 151.8 | X298: 162.3 | Y298: 146.6 | Z298: 153.2 | AA298: 160.3 | AB298: 155.4 | AC298: 154.4 | AD298: 157.8 | AE298: 2021-04 | AF298: =TEXT(AE298, "YYYY-MM") -> 2021-04
A299: Rural | B299: 2021 | C299: May | D299: 145.1 | E299: 198.5 | F299: 168.6 | G299: 155.8 | H299: 184.4 | I299: 162.3 | J299: 138.4 | K299: 165.1 | L299: 114.3 | M299: 169.7 | N299: 164.6 | O299: 169.8 | P299: 158.7 | Q299: 189.6 | R299: 165.3 | S299: 160.6 | T299: 164.5 | U299: 139.26 | V299: 161.7 | W299: 158.8 | X299: 169.1 | Y299: 153.2 | Z299: 160 | AA299: 167.6 | AB299: 159.3 | AC299: 161.1 | AD299: 161.1 | AE299: 2021-05 | AF299: =TEXT(AE299, "YYYY-MM") -> 2021-05
A300: Urban | B300: 2021 | C300: May | D300: 148.8 | E300: 204.3 | F300: 173 | G300: 156.5 | H300: 168.8 | I300: 172.5 | J300: 166.5 | K300: 165.9 | L300: 115.9 | M300: 165.2 | N300: 152 | O300: 171.1 | P300: 164.2 | Q300: 198.2 | R300: 156.5 | S300: 140.2 | T300: 154.1 | U300: 161.6 | V300: 155.5 | W300: 150.1 | X300: 160.4 | Y300: 145 | Z300: 152.6 | AA300: 156.6 | AB300: 157.5 | AC300: 152.3 | AD300: 159.5 | AE300: 2021-05 | AF300: =TEXT(AE300, "YYYY-MM") -> 2021-05
A301: Rural+Urban | B301: 2021 | C301: May | D301: 146.3 | E301: 200.5 | F301: 170.3 | G301: 156.1 | H301: 178.7 | I301: 167.1 | J301: 147.9 | K301: 165.4 | L301: 114.8 | M301: 168.2 | N301: 159.3 | O301: 170.4 | P301: 160.7 | Q301: 191.9 | R301: 161.8 | S301: 152.1 | T301: 160.4 | U301: 161.6 | V301: 159.4 | W301: 154.7 | X301: 165.8 | Y301: 148.9 | Z301: 155.8 | AA301: 161.2 | AB301: 158.6 | AC301: 156.8 | AD301: 160.4 | AE301: 2021-05 | AF301: =TEXT(AE301, "YYYY-MM") -> 2021-05
A302: Rural | B302: 2021 | C302: June | D302: 145.6 | E302: 200.1 | F302: 179.3 | G302: 156.1 | H302: 190.4 | I302: 158.6 | J302: 144.7 | K302: 165.5 | L302: 114.6 | M302: 170 | N302: 165.5 | O302: 171.7 | P302: 160.5 | Q302: 189.1 | R302: 165.3 | S302: 159.9 | T302: 164.6 | U302: 139.26 | V302: 162.1 | W302: 159.2 | X302: 169.7 | Y302: 154.2 | Z302: 160.4 | AA302: 166.8 | AB302: 159.4 | AC302: 161.5 | AD302: 162.1 | AE302: 2021-06 | AF302: =TEXT(AE302, "YYYY-MM") -> 2021-06
A303: Urban | B303: 2021 | C303: June | D303: 149.2 | E303: 205.5 | F303: 182.8 | G303: 156.5 | H303: 172.2 | I303: 171.5 | J303: 176.2 | K303: 166.9 | L303: 116.1 | M303: 165.5 | N303: 152.3 | O303: 173.3 | P303: 166.2 | Q303: 195.6 | R303: 157.3 | S303: 140.5 | T303: 154.8 | U303: 160.5 | V303: 156.1 | W303: 149.8 | X303: 160.8 | Y303: 147.5 | Z303: 150.7 | AA303: 158.1 | AB303: 158 | AC303: 153.4 | AD303: 160.4 | AE303: 2021-06 | AF303: =TEXT(AE303, "YYYY-MM") -> 2021-06
A304: Rural+Urban | B304: 2021 | C304: June | D304: 146.7 | E304: 202 | F304: 180.7 | G304: 156.2 | H304: 183.7 | I304: 164.6 | J304: 155.4 | K304: 166 | L304: 115.1 | M304: 168.5 | N304: 160 | O304: 172.4 | P304: 162.6 | Q304: 190.8 | R304: 162.2 | S304: 151.8 | T304: 160.7 | U304: 160.5 | V304: 159.8 | W304: 154.8 | X304: 166.3 | Y304: 150.7 | Z304: 154.9 | AA304: 161.7 | AB304: 158.8 | AC304: 157.6 | AD304: 161.3 | AE304: 2021-06 | AF304: =TEXT(AE304, "YYYY-MM") -> 2021-06
A305: Rural | B305: 2021 | C305: July | D305: 145.1 | E305: 204.5 | F305: 180.4 | G305: 157.1 | H305: 188.7 | I305: 157.7 | J305: 152.8 | K305: 163.6 | L305: 113.9 | M305: 169.7 | N305: 166.2 | O305: 171 | P305: 161.7 | Q305: 189.7 | R305: 166 | S305: 161.1 | T305: 165.3 | U305: 139.26 | V305: 162.5 | W305: 160.3 | X305: 170.4 | Y305: 157.1 | Z305: 160.7 | AA305: 167.2 | AB305: 160.4 | AC305: 162.8 | AD305: 163.2 | AE305: 2021-07 | AF305: =TEXT(AE305, "YYYY-MM") -> 2021-07
A306: Urban | B306: 2021 | C306: July | D306: 149.1 | E306: 210.9 | F306: 185 | G306: 158.2 | H306: 170.6 | I306: 170.9 | J306: 186.4 | K306: 164.7 | L306: 115.7 | M306: 165.5 | N306: 153.4 | O306: 173.5 | P306: 167.9 | Q306: 195.5 | R306: 157.9 | S306: 141.9 | T306: 155.5 | U306: 161.5 | V306: 157.7 | W306: 150.7 | X306: 161.5 | Y306: 149.5 | Z306: 151.2 | AA306: 160.3 | AB306: 159.6 | AC306: 155 | AD306: 161.8 | AE306: 2021-07 | AF306: =TEXT(AE306, "YYYY-MM") -> 2021-07
A307: Rural+Urban | B307: 2021 | C307: July | D307: 146.4 | E307: 206.8 | F307: 182.2 | G307: 157.5 | H307: 182.1 | I307: 163.9 | J307: 164.2 | K307: 164 | L307: 114.5 | M307: 168.3 | N307: 160.9 | O307: 172.2 | P307: 164 | Q307: 191.2 | R307: 162.8 | S307: 153.1 | T307: 161.4 | U307: 161.5 | V307: 160.7 | W307: 155.8 | X307: 167 | Y307: 153.1 | Z307: 155.3 | AA307: 163.2 | AB307: 160.1 | AC307: 159 | AD307: 162.5 | AE307: 2021-07 | AF307: =TEXT(AE307, "YYYY-MM") -> 2021-07
A308: Rural | B308: 2021 | C308: August | D308: 144.9 | E308: 202.3 | F308: 176.5 | G308: 157.5 | H308: 190.9 | I308: 155.7 | J308: 153.9 | K308: 162.8 | L308: 115.2 | M308: 169.8 | N308: 167.6 | O308: 171.9 | P308: 161.8 | Q308: 190.2 | R308: 167 | S308: 162.6 | T308: 166.3 | U308: 139.26 | V308: 163.1 | W308: 160.9 | X308: 171.1 | Y308: 157.7 | Z308: 161.1 | AA308: 167.5 | AB308: 160.3 | AC308: 163.3 | AD308: 163.6 | AE308: 2021-08 | AF308: =TEXT(AE308, "YYYY-MM") -> 2021-08
... A367: Rural+Urban | B367: 2023 | C367: March | D367: 174.4 | E367: 207.7 | F367: 175.2 | G367: 177.3 | H367: 179.2 | I367: 169.5 | J367: 152.8 | K367: 171.1 | L367: 120 | M367: 209.7 | N367: 172.3 | O367: 193 | P367: 177 | Q367: 199.5 | R367: 186.1 | S367: 178.7 | T367: 185.1 | U367: 173.5 | V367: 181.9 | W367: 174.2 | X367: 184.4 | Y367: 164.2 | Z367: 170.3 | AA367: 175 | AB367: 181 | AC367: 174.1 | AD367: 177.2 | AE367: 2023-03 | AF367: =TEXT(AE367, "YYYY-MM") -> 2023-03
A368: Rural | B368: 2023 | C368: April | D368: 173.3 | E368: 206.9 | F368: 167.9 | G368: 178.2 | H368: 178.5 | I368: 173.7 | J368: 142.8 | K368: 172.8 | L368: 120.4 | M368: 215.5 | N368: 178.2 | O368: 190.5 | P368: 175.5 | Q368: 199.5 | R368: 190.7 | S368: 187.3 | T368: 190.2 | U368: - | V368: 181.5 | W368: 179.1 | X368: 187.2 | Y368: 169.4 | Z368: 173.2 | AA368: 179.4 | AB368: 183.8 | AC368: 178.9 | AD368: 178.8 | AE368: 2023-04 | AF368: =TEXT(AE368, "YYYY-MM") -> 2023-04
A369: Urban | B369: 2023 | C369: April | D369: 174.8 | E369: 213.7 | F369: 172.4 | G369: 178.8 | H369: 168.7 | I369: 179.2 | J369: 179.9 | K369: 174.7 | L369: 123.1 | M369: 207.8 | N369: 165.5 | O369: 197 | P369: 182.1 | Q369: 203.5 | R369: 181 | S369: 167.7 | T369: 178.9 | U369: 175.2 | V369: 182.1 | W369: 169.6 | X369: 181.5 | Y369: 160.1 | Z369: 168.8 | AA369: 174.2 | AB369: 184.4 | AC369: 170.9 | AD369: 177.4 | AE369: 2023-04 | AF369: =TEXT(AE369, "YYYY-MM") -> 2023-04
A370: Rural+Urban | B370: 2023 | C370: April | D370: 173.8 | E370: 209.3 | F370: 169.6 | G370: 178.4 | H370: 174.9 | I370: 176.3 | J370: 155.4 | K370: 173.4 | L370: 121.3 | M370: 212.9 | N370: 172.9 | O370: 193.5 | P370: 177.9 | Q370: 200.6 | R370: 186.9 | S370: 179.2 | T370: 185.7 | U370: 175.2 | V370: 181.7 | W370: 174.6 | X370: 185 | Y370: 164.5 | Z370: 170.7 | AA370: 176.4 | AB370: 184 | AC370: 175 | AD370: 178.1 | AE370: 2023-04 | AF370: =TEXT(AE370, "YYYY-MM") -> 2023-04
A371: Rural | B371: 2023 | C371: May | D371: 173.2 | E371: 211.5 | F371: 171 | G371: 179.6 | H371: 173.3 | I371: 169 | J371: 148.7 | K371: 174.9 | L371: 121.9 | M371: 221 | N371: 178.7 | O371: 191.1 | P371: 176.8 | Q371: 199.9 | R371: 191.2 | S371: 187.9 | T371: 190.8 | U371: 139.26 | V371: 182.5 | W371: 179.8 | X371: 187.8 | Y371: 169.7 | Z371: 173.8 | AA371: 180.3 | AB371: 184.9 | AC371: 179.5 | AD371: 179.8 | AE371: 2023-05 | AF371: =TEXT(AE371, "YYYY-MM") -> 2023-05
A372: Urban | B372: 2023 | C372: May | D372: 174.7 | E372: 219.4 | F372: 176.7 | G372: 179.4 | H372: 164.4 | I372: 175.8 | J372: 185 | K372: 176.9 | L372: 124.2 | M372: 211.9 | N372: 165.9 | O372: 197.7 | P372: 183.1 | Q372: 204.2 | R372: 181.3 | S372: 168.1 | T372: 179.3 | U372: 175.6 | V372: 183.4 | W372: 170.1 | X372: 182.2 | Y372: 160.4 | Z372: 169.2 | AA372: 174.8 | AB372: 185.6 | AC372: 171.6 | AD372: 178.2 | AE372: 2023-05 | AF372: =TEXT(AE372, "YYYY-MM") -> 2023-05
A373: Rural+Urban | B373: 2023 | C373: May | D373: 173.7 | E373: 214.3 | F373: 173.2 | G373: 179.5 | H373: 170 | I373: 172.2 | J373: 161 | K373: 175.6 | L373: 122.7 | M373: 218 | N373: 173.4 | O373: 194.2 | P373: 179.1 | Q373: 201 | R373: 187.3 | S373: 179.7 | T373: 186.2 | U373: 175.6 | V373: 182.8 | W373: 175.2 | X373: 185.7 | Y373: 164.8 | Z373: 171.2 | AA373: 177.1 | AB373: 185.2 | AC373: 175.7 | AD373: 179.1 | AE373: 2023-05 | AF373: =TEXT(AE373, "YYYY-MM") -> 2023-05

Sheet Q1
A1: CPI calculation for latest month (MAY 2023)
A3: Boarder_category | B3: CPI Index | C3: Contribution | F3: Boarder_category | G3: CPI Index | H3: Contribution | K3: Boarder_category | L3: CPI Index | M3: Contribution
A4: Food and Beverages | B4: =SUM(All_India_Index_Upto_April23!D371:P371) -> 2290.7 | C4: =(B4/$B$13)*100% -> 0.49389184 | F4: Food and Beverages | G4: =SUM(All_India_Index_Upto_April23!D372:P372) -> 2335.1 | H4: =(G4/$B$13)*100% -> 0.50346481 | K4: Food and Beverages | L4: =SUM(All_India_Index_Upto_April23!D373:P373) -> 2306.9 | M4: =(L4/$B$13)*100% -> 0.49738468
A5: Tobacco & Intoxicants | B5: =SUM(All_India_Index_Upto_April23!Q371:Q371) -> 199.9 | C5: =(B5/$B$13)*100% -> 0.043099917 | F5: Tobacco & Intoxicants | G5: =SUM(All_India_Index_Upto_April23!Q372:Q372) -> 204.2 | H5: =(G5/$B$13)*100% -> 0.044027029 | K5: Tobacco & Intoxicants | L5: =SUM(All_India_Index_Upto_April23!Q373) -> 201 | M5: =(L5/$B$13)*100% -> 0.043337085
A6: Clothing & Footwear | B6: =SUM(All_India_Index_Upto_April23!R371:T371) -> 569.9 | C6: =(B6/$B$13)*100% -> 0.12287465 | F6: Clothing & Footwear | G6: =SUM(All_India_Index_Upto_April23!R372:T372) -> 528.7 | H6: =(G6/$B$13)*100% -> 0.11399163 | K6: Clothing & Footwear | L6: =SUM(All_India_Index_Upto_April23!R373:T373) -> 553.2 | M6: =(L6/$B$13)*100% -> 0.11927401
A7: Housing | B7: =SUM(All_India_Index_Upto_April23!U371:U371) -> 139.26 | C7: =(B7/$B$13)*100% -> 0.030025485 | F7: Housing | G7: =SUM(All_India_Index_Upto_April23!U372) -> 175.6 | H7: =(G7/$B$13)*100% -> 0.037860657 | K7: Housing | L7: =SUM(All_India_Index_Upto_April23!Z372) -> 169.2 | M7: =(L7/$B$13)*100% -> 0.03648077
A8: Fuel & Utilities | B8: =SUM(All_India_Index_Upto_April23!V371:W371) -> 362.3 | C8: =(B8/$B$13)*100% -> 0.078114557 | F8: Fuel & Utilities | G8: =SUM(All_India_Index_Upto_April23!V372:W372) -> 353.5 | H8: =(G8/$B$13)*100% -> 0.076217212 | K8: Fuel & Utilities | L8: =SUM(All_India_Index_Upto_April23!V373:W373) -> 358 | M8: =(L8/$B$13)*100% -> 0.077187445
A9: Health | B9: =SUM(All_India_Index_Upto_April23!X371:X371) -> 187.8 | C9: =(B9/$B$13)*100% -> 0.040491067 | F9: Health | G9: =SUM(All_India_Index_Upto_April23!X372:X372) -> 182.2 | H9: =(G9/$B$13)*100% -> 0.039283666 | K9: Health | L9: =SUM(All_India_Index_Upto_April23!X373) -> 185.7 | M9: =(L9/$B$13)*100% -> 0.040038292
A10: Transport & Communication | B10: =SUM(All_India_Index_Upto_April23!Y371:Y371) -> 169.7 | C10: =(B10/$B$13)*100% -> 0.036588574 | F10: Transport & Communication | G10: =SUM(All_India_Index_Upto_April23!Y372:Y372) -> 160.4 | H10: =(G10/$B$13)*100% -> 0.034583425 | K10: Transport & Communication | L10: =SUM(All_India_Index_Upto_April23!Y373) -> 164.8 | M10: =(L10/$B$13)*100% -> 0.035532097
A11: Education | B11: =SUM(All_India_Index_Upto_April23!AA371:AA371) -> 180.3 | C11: =(B11/$B$13)*100% -> 0.038874012 | F11: Education | G11: =SUM(All_India_Index_Upto_April23!AA372:AA372) -> 174.8 | H11: =(G11/$B$13)*100% -> 0.037688171 | K11: Education | L11: =SUM(All_India_Index_Upto_April23!AA373) -> 177.1 | M11: =(L11/$B$13)*100% -> 0.038184068
A12: Recreation & Miscellaneous | B12: =SUM(All_India_Index_Upto_April23!Z371:Z371, All_India_Index_Upto_April23!AB371:AC371) -> 538.2 | C12: =(B12/$B$13)*100% -> 0.1160399 | F12: Recreation & Miscellaneous | G12: =SUM(All_India_Index_Upto_April23!Z372:Z372, All_India_Index_Upto_April23!AB372:AC372) -> 526.4 | H12: =(G12/$B$13)*100% -> 0.11349573 | K12: Recreation & Miscellaneous | L12: =SUM(All_India_Index_Upto_April23!AB373:AC373,All_India_Index_Upto_April23!Z373) -> 532.1 | M12: =(L12/$B$13)*100% -> 0.11472469
A13: Total | B13: =SUM(B4:B12) -> 4638.06 | C13: =SUM(C4:C12) -> 1 | F13: Total | G13: =SUM(G4:G12) -> 4640.9 | H13: =SUM(H4:H12) -> 1.0006123 | K13: Total | L13: =SUM(L4:L12) -> 4648 | M13: =SUM(M4:M12) -> 1.0021431
F34: In all the 3 sector, Food and Beverages contribute to hightest CPI Index

Sheet Q2
A1: Sector | B1: Rural+Urban
A3: Row Labels | B3: Average of Cereals and products | C3: Average of Meat and fish | D3: Average of Egg | E3: Average of Milk and products | F3: Average of Oils and fats | G3: Average of Fruits | H3: Average of Vegetables | I3: Average of Pulses and products | J3: Average of Sugar and Confectionery | K3: Average of Spices | L3: Average of Non-alcoholic beverages | M3: Average of Prepared meals, s149.08cks, sweets etc. | N3: Average of Food and beverages | O3: Average of Pan, tobacco and intoxicants | P3: Average of Clothing | Q3: Average of Footwear | R3: Average of Clothing and footwear | S3: Average of Fuel and light | T3: Average of Housing | U3: Average of Household goods and services | V3: Average of Health | W3: Average of Transport and communication | X3: Average of Recreation and amusement | Y3: Average of Education | Z3: Average of Perso133.35l care and effects | AA3: Average of Miscellaneous | AB3: Average of General index | AD3: Total
A4: 2013 | B4: 114.08333 | C4: 113.6 | D4: 112.20833 | E4: 108.40833 | F4: 105.15833 | G4: 108.875 | H4: 133.75833 | I4: 106.49167 | J4: 103.43333 | K4: 106.075 | L4: 108.875 | M4: 112.175 | N4: 113.25 | O4: 109.675 | P4: 110.23333 | Q4: 108.74167 | R4: 110 | S4: 108.63333 | T4: 105.60833 | U4: 108 | V4: 106.76667 | W4: 106.675 | X4: 105.89167 | Y4: 107.71667 | Z4: 104.975 | AA4: 106.75833 | AB4: 110.03333 | AD4: =SUM(B4:AB4) -> 2956.1
A5: 2014 | B5: 121.78333 | C5: 122.03333 | D5: 119.20833 | E5: 119.83333 | F5: 107.51667 | G5: 124.79167 | H5: 139.04167 | I5: 113.125 | J5: 102.04167 | K5: 115.05 | L5: 114.48333 | M5: 121.9 | N5: 121.275 | O5: 118.39167 | P5: 119.14167 | Q5: 115.91667 | R5: 118.66667 | S5: 113.61667 | T5: 114.675 | U5: 114.91667 | V5: 112.64167 | W5: 111.50833 | X5: 111.9 | Y5: 115.55 | Z5: 109.11667 | AA5: 112.55 | AB5: 117.35 | AD5: =SUM(B5:AB5) -> 3148.025
A6: 2015 | B6: 124.18333 | C6: 128.86667 | D6: 119.81667 | E6: 127.68333 | F6: 111.21667 | G6: 129.59167 | H6: 143.38333 | I6: 141.35 | J6: 94.308333 | K6: 125.8 | L6: 119.725 | M6: 130.85 | N6: 127.65 | O6: 129.43333 | P6: 126.41667 | Q6: 122.13333 | R6: 125.775 | S6: 119.64167 | T6: 120.15833 | U6: 121.075 | V6: 118.55833 | W6: 111.09167 | X6: 117.04167 | Y6: 123.21667 | Z6: 112.425 | AA6: 116.43333 | AB6: 123.10833 | AD6: =SUM(B6:AB6) -> 3310.9333
A7: 2016 | B7: 128.5 | C7: 137.63333 | D7: 128.925 | E7: 132.70833 | F7: 116.25 | G7: 133.13333 | H7: 144.58333 | I7: 171.075 | J7: 108.55833 | K7: 136.66667 | L7: 124.7 | M7: 138.60833 | N7: 134.46667 | O7: 139.04167 | P7: 133.26667 | Q7: 127.5 | R7: 132.43333 | S7: 123.625 | T7: 126.475 | U7: 126.68333 | V7: 124.375 | W7: 113.39167 | X7: 122.05833 | Y7: 129.85833 | Z7: 119.58333 | AA7: 121.41667 | AB7: 129.2 | AD7: =SUM(B7:AB7) -> 3504.7167
A8: 2017 | B8: 133.98333 | C8: 141.825 | D8: 131.58333 | E8: 138.33333 | F8: 118.75833 | G8: 139.925 | H8: 143.70833 | I8: 138.56667 | J8: 119.825 | K8: 136.71667 | L8: 128.01667 | M8: 145.79167 | N8: 136.90833 | O8: 148.26667 | P8: 139.51667 | Q8: 132.31667 | R8: 138.48333 | S8: 130.50833 | T8: 133.675 | U8: 131.86667 | V8: 129.54167 | W8: 117.33333 | X8: 126.55 | Y8: 136 | Z8: 124.14167 | AA8: 126.25833 | AB8: 133.5 | AD8: =SUM(B8:AB8) -> 3601.9
A9: 2018 | B9: 137.05833 | C9: 146.925 | D9: 137.58333 | E9: 141.91667 | F9: 121.25 | G9: 147 | H9: 144.14167 | I9: 122.36667 | J9: 113.53333 | K9: 138.96667 | L9: 130.8 | M9: 152.24167 | N9: 139.175 | O9: 158.48333 | P9: 146.26667 | Q9: 137.79167 | R9: 145.03333 | S9: 139.775 | T9: 143.84167 | U9: 138.575 | V9: 137.58333 | W9: 123.125 | X9: 133.05833 | Y9: 143.89167 | Z9: 129.975 | AA9: 133.01667 | AB9: 138.775 | AD9: =SUM(B9:AB9) -> 3722.15
A10: 2019 | B10: 139.78182 | C10: 159.11818 | D10: 141.2 | E10: 144.33636 | F10: 122.98182 | G10: 144.55455 | H10: 163 | I10: 128.66364 | J10: 111.5 | K10: 142.6 | L10: 134.50909 | M10: 156.20909 | N10: 144.60909 | O10: 165.46364 | P10: 148.81818 | Q10: 140.38182 | R10: 147.59091 | S10: 140.24545 | T10: 150.76364 | U10: 144.36364 | V10: 147.84545 | W10: 125.59091 | X10: 139.91818 | Y10: 153.23636 | Z10: 136.59091 | AA10: 139.45455 | AB10: 144.18182 | AD10: =SUM(B10:AB10) -> 3857.5091
A11: 2020 | B11: 146.365 | C11: 179.06 | D11: 155.06642 | E11: 151.94375 | F11: 136.44333 | G11: 146.77 | H11: 183.071 | I11: 148.69417 | J11: 114.935 | K11: 156.885 | L11: 140.1225 | M11: 159.67167 | N11: 155.10917 | O11: 175.81333 | P11: 151.02667 | Q11: 142.37 | R11: 149.75333 | S11: 143.52583 | T11: 154.34667 | U11: 145.82333 | V11: 152.9675 | W11: 133.60333 | X11: 144.17333 | Y11: 154.66333 | Z11: 148.70833 | AA11: 145.38 | AB11: 151.07667 | AD11: =SUM(B11:AB11) -> 4067.3687
A12: 2021 | B12: 146.20833 | C12: 199.09167 | D12: 172.775 | E12: 156.96667 | F12: 177.7 | G12: 157.88333 | H12: 167.71667 | I12: 163.26667 | J12: 116.85 | K12: 167.3 | L12: 159.84167 | M12: 171.64167 | N12: 162.79167 | O12: 190.65 | P12: 162.21667 | Q12: 152.49167 | R12: 160.81667 | S12: 159.05833 | T12: 161.48333 | U12: 155.175 | V12: 165.84167 | W12: 150.55833 | X12: 155.6 | Y12: 162.11667 | Z12: 158.74167 | AA12: 157.60833 | AB12: 161.45833 | AD12: =SUM(B12:AB12) -> 4373.85
A13: 2022 | B13: 157.90833 | C13: 209.68333 | D13: 173.05833 | E13: 166.6 | F13: 192.31667 | G13: 164.46667 | H13: 178.13333 | I13: 166.40833 | J13: 120.38333 | K13: 188.825 | L13: 167.78333 | M13: 184.075 | N13: 173.575 | O13: 194.75 | P13: 177.25833 | Q13: 169.94167 | R13: 176.2 | S13: 175.13333 | T13: 168.05 | U13: 166.71667 | V13: 175.925 | W13: 161.09167 | X13: 165.69167 | Y13: 169.825 | Z13: 169.54167 | AA13: 167.78333 | AB13: 172.15 | AD13: =SUM(B13:AB13) -> 4653.275
A14: 2023 | B14: 174.02 | C14: 209.94 | D14: 177.54 | E14: 177.42 | F14: 178.12 | G14: 169.16 | H14: 155.16 | I14: 172.4 | J14: 121.02 | K14: 211.74 | L14: 172.46 | M14: 192.98 | N14: 177.54 | O14: 199.76 | P14: 186.28 | Q14: 178.78 | R14: 185.18 | S14: 182.1 | T14: 173.98 | U14: 174.22 | V14: 184.36 | W14: 164.26 | X14: 170.4 | Y14: 175.56 | Z14: 181.96 | AA14: 174.34 | AB14: 177.62 | AD14: =SUM(B14:AB14) -> 4798.3
A15: Grand Total | B15: 136.52081 | C15: 156.005 | D15: 140.67417 | E15: 140.38327 | F15: 132.92516 | G15: 140.8479 | H15: 154.02623 | I15: 141.39863 | J15: 110.95177 | K15: 144.31226 | L15: 134.46831 | M15: 149.08597 | N15: 142.32911 | O15: 154.78194 | P15: 143.16548 | Q15: 136.68177 | R15: 142.22048 | S15: 137.22105 | T15: 139.25855 | U15: 136.81516 | V15: 139.02024 | W15: 126.96242 | X15: 133.66677 | Y15: 140.94726 | Z15: 133.37742 | AA15: 134.29161 | AB15: 139.62839
